Workbook

Sheet Intro
B2: This spreadsheet was developed by Reed Miller
C3: reed.miller@maine.edu
C4: Assistant Professor at University of Maine
C5: Department of Civil and Environmental Engineering
C6: 45455
B8: It is associated with the RMI Contrail Impact Task Force Roadmap document.
B9: Chapter 4: Deciding When to Avoid Contrails - the Importance of Metrics
B10: Please cite Chapter 4 of the report when using the spreadsheet.
B11: Cathcart J, Andrews S, Chen A, et al. 4. Deciding When to Avoid Contrails — the Importance of Metrics. In: Understanding Contrail Management: Opportunities, Challenges, and Insights. RMI; 2024. https://rmi.org/insight/understanding-contrail-management-opportunities-challenges-and-insights
B13: The Contrail Severity Index concept is attributed to Marc Shapiro, Breakthrough Energy LLC.

Sheet GWP Decision Matrix
B2: Select Time Horizon and Aircraft Type: | G2: Override default values with custom input: | M2: Impact Calculations:
D3: Selections: | H3: Contrail ERF / RF | I3: Fuel burn (kg fuel / km) | J3: Fuel Burn WTWa impact (kg CO2e / kg fuel) | K3: AGWP (Wm-2 yr kg CO2-1) | M3: Contrail impact (kg CO2e/J) | N3: Fuel Burn WTWa impact (kg CO2e / km)
C4: GWP Time Horizon: | D4: 100 | G4: Default: | H4: 0.42 | I4: =INDEX('Background Data'!$D$8:$D$12,MATCH(D5,'Background Data'!$C$8:$C$12,0)) -> 4.1194409 | J4: =INDEX('Background Data'!$C$71:$D$71,MATCH("GWP"&D4,'Background Data'!$C$67:$D$67,0)) -> 5.1977958 | K4: =INDEX('Background Data'!$F$109:F$111,MATCH($D$4,'Background Data'!$B$109:$B$111,0)) -> 8.95e-14
C5: GREET Aircraft: | D5: Single Aisle (SA) | G5: Custom:
G6: Final: | H6: =IF(ISBLANK(H5),H4,H5) -> 0.42 | I6: =IF(ISBLANK(I5),I4,I5) -> 4.1194409 | J6: =IF(ISBLANK(J5),J4,J5) -> 5.1977958 | K6: =IF(ISBLANK(K5),K4,K5) -> 8.95e-14 | M6: =H6/('Background Data'!D104*'Background Data'!D105*'GWP Decision Matrix'!K6) -> 2.9171874e-10 | N6: =I6*J6 -> 21.412013
B8: Contrails | F8: ="Savings from Avoiding Contrails (GWP"&D4&", kg CO2e per km flight)" -> Savings from Avoiding Contrails (GWP100, kg CO2e per km flight) | P8: Contrail Avoidance Action
B9: Contrail Severity | C9: EF Percentile | D9: EF per flight distance | E9: Contrail Impact | F9: Impact from Contrails - Impact from Additional Fuel Burn due to Contrail Avoidance
C10: (Year 2019) | D10: (J/m) | E10: (kg CO2e/km)
B11: High | C11: 99 | D11: =_xlfn.XLOOKUP(C11,'Background Data'!$F$80:$F$100,'Background Data'!$G$80:$G$100) -> 3140000000 | E11: =D11*1000*$M$6 -> 915.99683 | F11: =$E11-F$33 -> 915.99683 | G11: =$E11-G$33 -> 915.99469 | H11: =$E11-H$33 -> 915.98613 | I11: =$E11-I$33 -> 915.97542 | J11: =$E11-J$33 -> 915.88977 | K11: =$E11-K$33 -> 915.78271 | L11: =$E11-L$33 -> 914.92623 | M11: =$E11-M$33 -> 913.85563 | ... O11: =$E11-O$33 -> 894.58482 | P11: If Positive (+) Savings, Avoid Contrails.
C12: 95 | D12: =_xlfn.XLOOKUP(C12,'Background Data'!$F$80:$F$100,'Background Data'!$G$80:$G$100) -> 1630000000 | E12: =D12*1000*$M$6 -> 475.50154 | F12: =$E12-F$33 -> 475.50154 | G12: =$E12-G$33 -> 475.4994 | H12: =$E12-H$33 -> 475.49084 | I12: =$E12-I$33 -> 475.48013 | J12: =$E12-J$33 -> 475.39448 | K12: =$E12-K$33 -> 475.28742 | L12: =$E12-L$33 -> 474.43094 | M12: =$E12-M$33 -> 473.36034 | ... O12: =$E12-O$33 -> 454.08953
C13: 90 | D13: =_xlfn.XLOOKUP(C13,'Background Data'!$F$80:$F$100,'Background Data'!$G$80:$G$100) -> 1010000000 | E13: =D13*1000*$M$6 -> 294.63592 | F13: =$E13-F$33 -> 294.63592 | G13: =$E13-G$33 -> 294.63378 | H13: =$E13-H$33 -> 294.62522 | I13: =$E13-I$33 -> 294.61451 | J13: =$E13-J$33 -> 294.52886 | K13: =$E13-K$33 -> 294.4218 | L13: =$E13-L$33 -> 293.56532 | M13: =$E13-M$33 -> 292.49472 | ... O13: =$E13-O$33 -> 273.22391
C14: 85 | D14: =_xlfn.XLOOKUP(C14,'Background Data'!$F$80:$F$100,'Background Data'!$G$80:$G$100) -> 672000000 | E14: =D14*1000*$M$6 -> 196.03499 | F14: =$E14-F$33 -> 196.03499 | G14: =$E14-G$33 -> 196.03285 | H14: =$E14-H$33 -> 196.02429 | I14: =$E14-I$33 -> 196.01358 | J14: =$E14-J$33 -> 195.92793 | K14: =$E14-K$33 -> 195.82087 | L14: =$E14-L$33 -> 194.96439 | M14: =$E14-M$33 -> 193.89379 | ... O14: =$E14-O$33 -> 174.62298
B15: Medum | C15: 80 | D15: =_xlfn.XLOOKUP(C15,'Background Data'!$F$80:$F$100,'Background Data'!$G$80:$G$100) -> 457000000 | E15: =D15*1000*$M$6 -> 133.31546 | F15: =$E15-F$33 -> 133.31546 | G15: =$E15-G$33 -> 133.31332 | H15: =$E15-H$33 -> 133.30476 | I15: =$E15-I$33 -> 133.29405 | J15: =$E15-J$33 -> 133.2084 | K15: =$E15-K$33 -> 133.10134 | L15: =$E15-L$33 -> 132.24486 | M15: =$E15-M$33 -> 131.17426 | ... O15: =$E15-O$33 -> 111.90345
C16: 75 | D16: =_xlfn.XLOOKUP(C16,'Background Data'!$F$80:$F$100,'Background Data'!$G$80:$G$100) -> 307000000 | E16: =D16*1000*$M$6 -> 89.557652 | F16: =$E16-F$33 -> 89.557652 | G16: =$E16-G$33 -> 89.555511 | H16: =$E16-H$33 -> 89.546946 | I16: =$E16-I$33 -> 89.53624 | J16: =$E16-J$33 -> 89.450592 | K16: =$E16-K$33 -> 89.343532 | L16: =$E16-L$33 -> 88.487052 | M16: =$E16-M$33 -> 87.416451 | ... O16: =$E16-O$33 -> 68.14564
C17: 70 | D17: =_xlfn.XLOOKUP(C17,'Background Data'!$F$80:$F$100,'Background Data'!$G$80:$G$100) -> 200000000 | E17: =D17*1000*$M$6 -> 58.343747 | F17: =$E17-F$33 -> 58.343747 | G17: =$E17-G$33 -> 58.341606 | H17: =$E17-H$33 -> 58.333041 | I17: =$E17-I$33 -> 58.322335 | J17: =$E17-J$33 -> 58.236687 | K17: =$E17-K$33 -> 58.129627 | L17: =$E17-L$33 -> 57.273147 | M17: =$E17-M$33 -> 56.202546 | ... O17: =$E17-O$33 -> 36.931735
C18: 65 | D18: =_xlfn.XLOOKUP(C18,'Background Data'!$F$80:$F$100,'Background Data'!$G$80:$G$100) -> 123000000 | E18: =D18*1000*$M$6 -> 35.881405 | F18: =$E18-F$33 -> 35.881405 | G18: =$E18-G$33 -> 35.879263 | H18: =$E18-H$33 -> 35.870699 | I18: =$E18-I$33 -> 35.859993 | J18: =$E18-J$33 -> 35.774345 | K18: =$E18-K$33 -> 35.667285 | L18: =$E18-L$33 -> 34.810804 | M18: =$E18-M$33 -> 33.740203 | ... O18: =$E18-O$33 -> 14.469392 | P18: If Negative (-) Savings, Don't Avoid Contrails.
C19: 60 | D19: =_xlfn.XLOOKUP(C19,'Background Data'!$F$80:$F$100,'Background Data'!$G$80:$G$100) -> 70600000 | E19: =D19*1000*$M$6 -> 20.595343 | F19: =$E19-F$33 -> 20.595343 | G19: =$E19-G$33 -> 20.593202 | H19: =$E19-H$33 -> 20.584637 | I19: =$E19-I$33 -> 20.573931 | J19: =$E19-J$33 -> 20.488283 | K19: =$E19-K$33 -> 20.381223 | L19: =$E19-L$33 -> 19.524742 | M19: =$E19-M$33 -> 18.454142 | ... O19: =$E19-O$33 -> -0.81666967
C20: 55 | D20: =_xlfn.XLOOKUP(C20,'Background Data'!$F$80:$F$100,'Background Data'!$G$80:$G$100) -> 37200000 | E20: =D20*1000*$M$6 -> 10.851937 | F20: =$E20-F$33 -> 10.851937 | G20: =$E20-G$33 -> 10.849796 | H20: =$E20-H$33 -> 10.841231 | I20: =$E20-I$33 -> 10.830525 | J20: =$E20-J$33 -> 10.744877 | K20: =$E20-K$33 -> 10.637817 | L20: =$E20-L$33 -> 9.7813364 | M20: =$E20-M$33 -> 8.7107358 | ... O20: =$E20-O$33 -> -10.560075
B21: Low | C21: 50 | D21: =_xlfn.XLOOKUP(C21,'Background Data'!$F$80:$F$100,'Background Data'!$G$80:$G$100) -> 17400000 | E21: =D21*1000*$M$6 -> 5.075906 | F21: =$E21-F$33 -> 5.075906 | G21: =$E21-G$33 -> 5.0737648 | H21: =$E21-H$33 -> 5.0652 | I21: =$E21-I$33 -> 5.054494 | J21: =$E21-J$33 -> 4.968846 | K21: =$E21-K$33 -> 4.8617859 | L21: =$E21-L$33 -> 4.0053054 | M21: =$E21-M$33 -> 2.9347048 | ... O21: =$E21-O$33 -> -16.336106
C22: 45 | D22: =_xlfn.XLOOKUP(C22,'Background Data'!$F$80:$F$100,'Background Data'!$G$80:$G$100) -> 6310000 | E22: =D22*1000*$M$6 -> 1.8407452 | F22: =$E22-F$33 -> 1.8407452 | G22: =$E22-G$33 -> 1.838604 | H22: =$E22-H$33 -> 1.8300392 | I22: =$E22-I$33 -> 1.8193332 | J22: =$E22-J$33 -> 1.7336852 | K22: =$E22-K$33 -> 1.6266251 | L22: =$E22-L$33 -> 0.77014461 | M22: =$E22-M$33 -> -0.30045602 | ... O22: =$E22-O$33 -> -19.571267
C23: 40 | D23: =_xlfn.XLOOKUP(C23,'Background Data'!$F$80:$F$100,'Background Data'!$G$80:$G$100) -> 905000 | E23: =D23*1000*$M$6 -> 0.26400546 | F23: =$E23-F$33 -> 0.26400546 | G23: =$E23-G$33 -> 0.26186426 | H23: =$E23-H$33 -> 0.25329945 | I23: =$E23-I$33 -> 0.24259344 | J23: =$E23-J$33 -> 0.15694539 | K23: =$E23-K$33 -> 0.049885332 | L23: =$E23-L$33 -> -0.80659517 | M23: =$E23-M$33 -> -1.8771958 | ... O23: =$E23-O$33 -> -21.148007
B24: Very Low | D24: =D23/1000 -> 905 | E24: =D24*1000*$M$6 -> 0.00026400546 | F24: =$E24-F$33 -> 0.00026400546 | G24: =$E24-G$33 -> -0.0018771958 | H24: =$E24-H$33 -> -0.010442001 | I24: =$E24-I$33 -> -0.021148007 | J24: =$E24-J$33 -> -0.10679606 | K24: =$E24-K$33 -> -0.21385612 | L24: =$E24-L$33 -> -1.0703366 | M24: =$E24-M$33 -> -2.1409372 | ... O24: =$E24-O$33 -> -21.411748
B25: Cooling | C25: 35 | D25: =_xlfn.XLOOKUP(C25,'Background Data'!$F$80:$F$100,'Background Data'!$G$80:$G$100) -> -274000 | E25: =D25*1000*$M$6 -> -0.079930934 | F25: =$E25-F$33 -> -0.079930934 | G25: =$E25-G$33 -> -0.082072135 | H25: =$E25-H$33 -> -0.09063694 | I25: =$E25-I$33 -> -0.10134295 | J25: =$E25-J$33 -> -0.186991 | K25: =$E25-K$33 -> -0.29405106 | L25: =$E25-L$33 -> -1.1505316 | M25: =$E25-M$33 -> -2.2211322 | ... O25: =$E25-O$33 -> -21.491943 | P25: Don't Avoid Cooling (-) Contrails.
C26: 30 | D26: =_xlfn.XLOOKUP(C26,'Background Data'!$F$80:$F$100,'Background Data'!$G$80:$G$100) -> -1470000 | E26: =D26*1000*$M$6 -> -0.42882654 | F26: =$E26-F$33 -> -0.42882654 | G26: =$E26-G$33 -> -0.43096774 | H26: =$E26-H$33 -> -0.43953255 | I26: =$E26-I$33 -> -0.45023856 | J26: =$E26-J$33 -> -0.53588661 | K26: =$E26-K$33 -> -0.64294667 | L26: =$E26-L$33 -> -1.4994272 | M26: =$E26-M$33 -> -2.5700278 | ... O26: =$E26-O$33 -> -21.840839
C27: 25 | D27: =_xlfn.XLOOKUP(C27,'Background Data'!$F$80:$F$100,'Background Data'!$G$80:$G$100) -> -2690000 | E27: =D27*1000*$M$6 -> -0.7847234 | F27: =$E27-F$33 -> -0.7847234 | G27: =$E27-G$33 -> -0.7868646 | H27: =$E27-H$33 -> -0.79542941 | I27: =$E27-I$33 -> -0.80613542 | J27: =$E27-J$33 -> -0.89178347 | K27: =$E27-K$33 -> -0.99884353 | L27: =$E27-L$33 -> -1.855324 | M27: =$E27-M$33 -> -2.9259247 | ... O27: =$E27-O$33 -> -22.196736
C28: 20 | D28: =_xlfn.XLOOKUP(C28,'Background Data'!$F$80:$F$100,'Background Data'!$G$80:$G$100) -> -7780000 | E28: =D28*1000*$M$6 -> -2.2695718 | F28: =$E28-F$33 -> -2.2695718 | G28: =$E28-G$33 -> -2.271713 | H28: =$E28-H$33 -> -2.2802778 | I28: =$E28-I$33 -> -2.2909838 | J28: =$E28-J$33 -> -2.3766318 | K28: =$E28-K$33 -> -2.4836919 | L28: =$E28-L$33 -> -3.3401724 | M28: =$E28-M$33 -> -4.410773 | ... O28: =$E28-O$33 -> -23.681584
C29: 15 | D29: =_xlfn.XLOOKUP(C29,'Background Data'!$F$80:$F$100,'Background Data'!$G$80:$G$100) -> -24500000 | E29: =D29*1000*$M$6 -> -7.1471091 | F29: =$E29-F$33 -> -7.1471091 | G29: =$E29-G$33 -> -7.1492503 | H29: =$E29-H$33 -> -7.1578151 | I29: =$E29-I$33 -> -7.1685211 | J29: =$E29-J$33 -> -7.2541691 | K29: =$E29-K$33 -> -7.3612292 | L29: =$E29-L$33 -> -8.2177097 | M29: =$E29-M$33 -> -9.2883103 | ... O29: =$E29-O$33 -> -28.559122
C30: 10 | D30: =_xlfn.XLOOKUP(C30,'Background Data'!$F$80:$F$100,'Background Data'!$G$80:$G$100) -> -69300000 | E30: =D30*1000*$M$6 -> -20.216108 | F30: =$E30-F$33 -> -20.216108 | G30: =$E30-G$33 -> -20.21825 | H30: =$E30-H$33 -> -20.226814 | I30: =$E30-I$33 -> -20.23752 | J30: =$E30-J$33 -> -20.323169 | K30: =$E30-K$33 -> -20.430229 | L30: =$E30-L$33 -> -21.286709 | M30: =$E30-M$33 -> -22.35731 | ... O30: =$E30-O$33 -> -41.628121
C31: 5 | D31: =_xlfn.XLOOKUP(C31,'Background Data'!$F$80:$F$100,'Background Data'!$G$80:$G$100) -> -195000000 | E31: =D31*1000*$M$6 -> -56.885154 | F31: =$E31-F$33 -> -56.885154 | G31: =$E31-G$33 -> -56.887295 | H31: =$E31-H$33 -> -56.89586 | I31: =$E31-I$33 -> -56.906566 | J31: =$E31-J$33 -> -56.992214 | K31: =$E31-K$33 -> -57.099274 | L31: =$E31-L$33 -> -57.955754 | M31: =$E31-M$33 -> -59.026355 | ... O31: =$E31-O$33 -> -78.297166
C32: 1 | D32: =_xlfn.XLOOKUP(C32,'Background Data'!$F$80:$F$100,'Background Data'!$G$80:$G$100) -> -639000000 | E32: =D32*1000*$M$6 -> -186.40827 | F32: =$E32-F$33 -> -186.40827 | G32: =$E32-G$33 -> -186.41041 | H32: =$E32-H$33 -> -186.41898 | I32: =$E32-I$33 -> -186.42968 | J32: =$E32-J$33 -> -186.51533 | K32: =$E32-K$33 -> -186.62239 | L32: =$E32-L$33 -> -187.47887 | M32: =$E32-M$33 -> -188.54947 | ... O32: =$E32-O$33 -> -207.82029
E33: Additional fuel burn impact (kg CO2e/km) | F33: =F34*$J$6 -> 0 | G33: =G34*$J$6 -> 0.0021412013 | H33: =H34*$J$6 -> 0.010706006 | I33: =I34*$J$6 -> 0.021412013 | J33: =J34*$J$6 -> 0.10706006 | K33: =K34*$J$6 -> 0.21412013 | L33: =L34*$J$6 -> 1.0706006 | M33: =M34*$J$6 -> 2.1412013 | ... O33: =O34*$J$6 -> 21.412013
E34: Additional fuel burn (kg/km) | F34: =F35*$I$6 -> 0 | G34: =G35*$I$6 -> 0.00041194409 | H34: =H35*$I$6 -> 0.0020597205 | I34: =I35*$I$6 -> 0.0041194409 | J34: =J35*$I$6 -> 0.020597205 | K34: =K35*$I$6 -> 0.041194409 | L34: =L35*$I$6 -> 0.20597205 | M34: =M35*$I$6 -> 0.41194409 | ... O34: =O35*$I$6 -> 4.1194409
E35: Additional fuel burn (%) | F35: 0 | G35: 0.0001 | H35: 0.0005 | I35: 0.001 | J35: 0.005 | K35: 0.01 | L35: 0.05 | M35: 0.1 | N35: 0.5 | O35: 1
F36: Low | K36: Medium | L36: High | N36: Very High
F37: Additional Fuel Burn due to Contrail Avoidance

Sheet Background Data
B1: Background Data and Calculations
B3: Additional Fuel Burn
B5: GREET1 2023
B6: Source: JetFuel_PTWa, Table 3
B7: Aircraft Type | C7: Aircraft Class | D7: Fuel Intensity, kg per km (kg fuel/km great circle distance) | E7: Average Trip Great Circle Distance (km/operation) | F7: As-Operated Aircraft Average Trip Petroleum Jet Fuel Consumption (kg/operation)
B8: Passenger Aircraft | C8: Regional Jet (RJ) | D8: 2.9577114 | E8: 804 | F8: 2378
C9: Single Aisle (SA) | D9: 4.1194409 | E9: 1574 | F9: 6484
C10: Small Twin Aisle (STA) | D10: 6.0926346 | E10: 4847 | F10: 29531
C11: Large Twin Aisle (LTA) | D11: 7.7752452 | E11: 6932 | F11: 53898
C12: Large Quad (LQ) | D12: 12.927069 | E12: 3757 | F12: 48567
B13: Freight Aircraft | C13: Single Aisle (SA-F) | D13: 5.2502415 | E13: 1035 | F13: 5434
C14: Small Twin Aisle (STA-F) | D14: 7.8114669 | E14: 1936 | F14: 15123
C15: Large Twin Aisle (LTA-F) | D15: 8.7127273 | E15: 2200 | F15: 19168
C16: Large Quad (LQ-F) | D16: 13.280228 | E16: 4921 | F16: 65352
B18: Source: JetFuel_WTP, Table 5 (result calculations based on formulas in JetFuel_WTWa)
B19: 5) Summary of Energy Consumption, Water Consumption and Emissions: J, or Gallon, or Grams per MJ of Fuel Throughput at Each Stage
B20: 5.1) Energy Consumption, Water Consumption, and Total Emissions
C21: GWP20, incl. SLCF | D21: GWP20, excl. SLCF | E21: GWP100, excl. SLCF | F21: GWP100, incl. SLCF
C22: Combined: Jet Fuel | D22: Combined: Jet Fuel | E22: Combined: Jet Fuel | F22: Combined: Jet Fuel
C23: Feedstock + Fuel | D23: Feedstock + Fuel | E23: Feedstock + Fuel | F23: Feedstock + Fuel
B24: Total energy | C24: 121638.75 | D24: 121638.75 | E24: 121638.75 | F24: 121638.75
B25: Fossi lfuels | C25: 116543.66 | D25: 116543.66 | E25: 116543.66 | F25: 116543.66
B26: Coal | C26: 7036.7364 | D26: 7036.7364 | E26: 7036.7364 | F26: 7036.7364
B27: Natural gas | C27: 77097.029 | D27: 77097.029 | E27: 77097.029 | F27: 77097.029
B28: Petroleum | C28: 32409.898 | D28: 32409.898 | E28: 32409.898 | F28: 32409.898
B29: Water consumption | C29: 0.019839314 | D29: 0.019839314 | E29: 0.019839314 | F29: 0.019839314
B30: VOC | C30: 0.0065242665 | D30: 0.0065242665 | E30: 0.0065242665 | F30: 0.0065242665
B31: CO | C31: 0.0096484916 | D31: 0.0096484916 | E31: 0.0096484916 | F31: 0.0096484916
B32: NOx | C32: 0.014777101 | D32: 0.014777101 | E32: 0.014777101 | F32: 0.014777101
B33: PM10 | C33: 0.00093013207 | D33: 0.00093013207 | E33: 0.00093013207 | F33: 0.00093013207
B34: PM2.5 | C34: 0.00078711454 | D34: 0.00078711454 | E34: 0.00078711454 | F34: 0.00078711454
B35: SOx | C35: 0.0036516669 | D35: 0.0036516669 | E35: 0.0036516669 | F35: 0.0036516669
... B42: GHGs (g CO2e/MJ) | C42: 16.916168 | D42: 16.126197 | E42: 11.136165 | F42: 11.124961
B43: GHGs (kg CO2e/kg fuel) | C43: =(C42/1000)*$B$53 -> 0.72401199 | D43: =(D42/1000)*$B$53 -> 0.69020122 | E43: =(E42/1000)*$B$53 -> 0.47662786 | F43: =(F42/1000)*$B$53 -> 0.47614833
B45: Source: Jing et al (2022) Fig 2 (For comparison)
C46: gCO2e / MJ, GWP 100
B47: WTP (GHGs) | C47: =9.6+5.3 -> 14.9
B48: Combustion (CO2 only) | C48: 73.8
B49: WTWa, sum | C49: =E42+C48 -> 84.936165
B52: ICAO conversion factors:
...
